[2023-01-05 09:32:12 +0000] [1771] [INFO] Starting gunicorn 20.1.0
[2023-01-05 09:32:12 +0000] [1771] [INFO] Listening at: http://0.0.0.0:8000 (1771)
[2023-01-05 09:32:12 +0000] [1771] [INFO] Using worker: sync
[2023-01-05 09:32:12 +0000] [1773] [INFO] Booting worker with pid: 1773
Exception in thread Thread-1:
Traceback (most recent call last):
  File "/usr/lib/python3.8/threading.py", line 932, in _bootstrap_inner
    self.run()
  File "/usr/lib/python3.8/threading.py", line 870, in run
    self._target(*self._args, **self._kwargs)
  File "/home/ubuntu/projects/solar-hybrid-inverter-monitor/inverter-api/libs/set_interval.py", line 20, in __setInterval
    self.action()
  File "/home/ubuntu/projects/solar-hybrid-inverter-monitor/inverter-api/libs/inverter.py", line 23, in getAll
    Inverter.QPIGS_RAW = sendCommand(dev, 'QPIGS')
  File "/home/ubuntu/projects/solar-hybrid-inverter-monitor/inverter-api/libs/utils.py", line 41, in sendCommand
    result = parseQPIGS(rawResult)
  File "/home/ubuntu/projects/solar-hybrid-inverter-monitor/inverter-api/libs/parsers.py", line 173, in parseQPIGS
    data[parameterMappings[currentIndex]] = parameter
IndexError: list index out of range
